<?xml version="1.0" encoding="UTF-8"?>
<testsuite name="java_testcases.junit.LEVENSHTEIN_TEST" tests="1" skipped="0" failures="1" errors="0" timestamp="2024-04-26T02:23:15" hostname="MacBook-Pro-685.local" time="0.011">
  <properties/>
  <testcase name="test_6" classname="java_testcases.junit.LEVENSHTEIN_TEST" time="0.011">
    <failure message="java.lang.AssertionError: expected:&lt;4&gt; but was:&lt;5&gt;" type="java.lang.AssertionError">java.lang.AssertionError: expected:&lt;4&gt; but was:&lt;5&gt;
	at org.junit.Assert.fail(Assert.java:88)
	at org.junit.Assert.failNotEquals(Assert.java:834)
	at org.junit.Assert.assertEquals(Assert.java:645)
	at org.junit.Assert.assertEquals(Assert.java:631)
	at java_testcases.junit.LEVENSHTEIN_TEST.test_6(LEVENSHTEIN_TEST.java:45)
	at sun.reflect.NativeMethodAccessorImpl.invoke0(Native Method)
	at sun.reflect.NativeMethodAccessorImpl.invoke(NativeMethodAccessorImpl.java:62)
	at sun.reflect.DelegatingMethodAccessorImpl.invoke(DelegatingMethodAccessorImpl.java:43)
	at java.lang.reflect.Method.invoke(Method.java:498)
	at org.junit.runners.model.FrameworkMethod$1.runReflectiveCall(FrameworkMethod.java:50)
	at org.junit.internal.runners.model.ReflectiveCallable.run(ReflectiveCallable.java:12)
	at org.junit.runners.model.FrameworkMethod.invokeExplosively(FrameworkMethod.java:47)
	at org.junit.internal.runners.statements.InvokeMethod.evaluate(InvokeMethod.java:17)
	at org.junit.internal.runners.statements.FailOnTimeout$CallableStatement.call(FailOnTimeout.java:298)
	at org.junit.internal.runners.statements.FailOnTimeout$CallableStatement.call(FailOnTimeout.java:292)
	at java.util.concurrent.FutureTask.run(FutureTask.java:266)
	at java.lang.Thread.run(Thread.java:750)
</failure>
  </testcase>
  <system-out><![CDATA[]]></system-out>
  <system-err><![CDATA[]]></system-err>
</testsuite>
